Workbook

Sheet Produtos
A1: COD | B1: Marca | C1: Coleção | D1: Categoria | E1: Produto | F1: Nome | G1: Unidade | H1: Volume | I1: Tipo | J1: Descrição | K1: Preço Custo | L1: Preço Venda | M1: Estoque | N1: Status estoque
A2: NATBRA-2816 | B2: Natura | C2: Tododia | D2: Hidrante Desodorante Corporal | E2: =TRIM(CONCATENATE(D2, " ", C2, " ", F2, " ", IF(G2>0, G2 & "x" & H2, H2), " ", I2)) | F2: Algodão | H2: 400ml | I2: Frasco | J2: Desodorante / nutritivo / creme | K2: 64 | L2: 75.9 | M2: =SUMIF(Movimento!B:B, A2, Movimento!F:F) | N2: =IF(M2=0,"Falta Pedir!",IF(M2<=3,"Baixo Estoque","Em Estoque"))
B3: Natura | C3: Tododia | D3: Hidrante Desodorante Corporal | E3: =TRIM(CONCATENATE(D3, " ", C3, " ", F3, " ", IF(G3>0, G3 & "x" & H3, H3), " ", I3)) | F3: Ameixa e Flor de Baunilha | H3: 400ml | I3: Frasco | J3: Suave de Algodão \ Nutritivo | L3: 75.9 | M3: =SUMIF(Movimento!B:B, A3, Movimento!F:F) | N3: =IF(M3=0,"Falta Pedir!",IF(M3<=3,"Baixo Estoque","Em Estoque"))
B4: Natura | C4: Tododia | D4: Hidrante Desodorante Corporal | E4: =TRIM(CONCATENATE(D4, " ", C4, " ", F4, " ", IF(G4>0, G4 & "x" & H4, H4), " ", I4)) | F4: Acerola e Hibisco | H4: 400ml | I4: Frasco | J4: Refrescante / Gelado | L4: 75.9
B5: Natura | C5: Tododia | D5: Hidrante Desodorante Corporal | E5: =TRIM(CONCATENATE(D5, " ", C5, " ", F5, " ", IF(G5>0, G5 & "x" & H5, H5), " ", I5)) | F5: Amora Vermelha e Jabuticaba | H5: 400ml | I5: Frasco | J5: Desodorante / nutritivo / creme | L5: 75.9
B6: Natura | C6: Tododia | D6: Hidrante Desodorante Corporal | E6: =TRIM(CONCATENATE(D6, " ", C6, " ", F6, " ", IF(G6>0, G6 & "x" & H6, H6), " ", I6)) | F6: Capim Limão e Hortelã | H6: 400ml | I6: Frasco | J6: Desodorante / nutritivo / creme | L6: 75.9
B7: Natura | C7: Tododia | D7: Hidrante Desodorante Corporal | E7: =TRIM(CONCATENATE(D7, " ", C7, " ", F7, " ", IF(G7>0, G7 & "x" & H7, H7), " ", I7)) | F7: Cereja Negra e Praliné | H7: 400ml | I7: Frasco | J7: Desodorante / nutritivo / creme | L7: 75.9
B8: Natura | C8: Tododia | D8: Hidrante Desodorante Corporal | E8: =TRIM(CONCATENATE(D8, " ", C8, " ", F8, " ", IF(G8>0, G8 & "x" & H8, H8), " ", I8)) | F8: Cereja e Avela | H8: 400ml | I8: Frasco | J8: Desodorante / nutritivo / creme | L8: 75.9
B9: Natura | C9: Tododia | D9: Hidrante Desodorante Corporal | E9: =TRIM(CONCATENATE(D9, " ", C9, " ", F9, " ", IF(G9>0, G9 & "x" & H9, H9), " ", I9)) | F9: Cereja e Avela | H9: 400ml | I9: Frasco | J9: HIdrata. Noturno \ Calmante \Chá de Camomila e Lavanda | L9: 75.9
B10: Natura | C10: Tododia | D10: Hidrante Desodorante Corporal | E10: =TRIM(CONCATENATE(D10, " ", C10, " ", F10, " ", IF(G10>0, G10 & "x" & H10, H10), " ", I10)) | F10: Todanoite | H10: 200ml | I10: Frasco | J10: HIdrata. Noturno \ Calmante \ Chá de Camomila e Lavanda | L10: 87.9
B11: Natura | C11: Tododia | D11: Hidrante Desodorante Corporal | E11: =TRIM(CONCATENATE(D11, " ", C11, " ", F11, " ", IF(G11>0, G11 & "x" & H11, H11), " ", I11)) | F11: Flor de Gengibre e Tangerina | H11: 400 ml | I11: Frasco | J11: Nutritivo Energizante | L11: 75.9
B12: Natura | C12: Tododia | D12: Hidrante Desodorante Corporal | E12: =TRIM(CONCATENATE(D12, " ", C12, " ", F12, " ", IF(G12>0, G12 & "x" & H12, H12), " ", I12)) | F12: Flor de Pera e Melissa | H12: 400ml | I12: Frasco | J12: Desodorante / nutritivo / creme | L12: 75.9
B13: Natura | C13: Tododia | D13: Hidrante Desodorante Corporal | E13: =TRIM(CONCATENATE(D13, " ", C13, " ", F13, " ", IF(G13>0, G13 & "x" & H13, H13), " ", I13)) | F13: Framboesa e PImenta Vermelha | H13: 400ml | I13: Frasco | J13: Desodorante / nutritivo / creme | L13: 75.9
B14: Natura | C14: Tododia | D14: Hidrante Desodorante Corporal | E14: =TRIM(CONCATENATE(D14, " ", C14, " ", F14, " ", IF(G14>0, G14 & "x" & H14, H14), " ", I14)) | F14: Jambo Rosa e Flor De Caju | H14: 400ml | I14: Frasco | J14: Desodorante / nutritivo / creme | L14: 75.9
B15: Natura | C15: Tododia | D15: Hidrante Desodorante Corporal | E15: =TRIM(CONCATENATE(D15, " ", C15, " ", F15, " ", IF(G15>0, G15 & "x" & H15, H15), " ", I15)) | F15: Limão Siciliano e Flor de Gardênia | H15: 400ml | I15: Frasco | J15: Desodorante / nutritivo / creme | L15: 75.9
... B23: Natura | C23: Tododia | D23: Hidrante Desodorante Corporal | E23: =TRIM(CONCATENATE(D23, " ", C23, " ", F23, " ", IF(G23>0, G23 & "x" & H23, H23), " ", I23)) | F23: Algodao | H23: 400ml | I23: Refil | J23: Desodorante / nutritivo / creme | L23: 56.4
A24: NATBRA-100423 | B24: Natura | C24: Tododia | D24: Hidrante Desodorante Corporal | E24: =TRIM(CONCATENATE(D24, " ", C24, " ", F24, " ", IF(G24>0, G24 & "x" & H24, H24), " ", I24)) | F24: Ameixa e Flor de Baunilha | H24: 400ml | I24: Refil | J24: Suave de Algodão \ Nutritivo | L24: 56.4
B25: Natura | C25: Tododia | D25: Hidrante Desodorante Corporal | E25: =TRIM(CONCATENATE(D25, " ", C25, " ", F25, " ", IF(G25>0, G25 & "x" & H25, H25), " ", I25)) | F25: Acerola e Hibisco | H25: 400ml | I25: Refil | J25: Refrescante / Gelado | L25: 56.4
B26: Natura | C26: Tododia | D26: Hidrante Desodorante Corporal | E26: =TRIM(CONCATENATE(D26, " ", C26, " ", F26, " ", IF(G26>0, G26 & "x" & H26, H26), " ", I26)) | F26: Amora Vermelha e Jabuticaba | H26: 400ml | I26: Refil | J26: Desodorante / nutritivo / creme | L26: 56.4
A27: NATBRA-190159 | B27: Natura | C27: Tododia | D27: Hidrante Desodorante Corporal | E27: =TRIM(CONCATENATE(D27, " ", C27, " ", F27, " ", IF(G27>0, G27 & "x" & H27, H27), " ", I27)) | F27: Capim Limão e Hortelã | H27: 400ml | I27: Refil | J27: Desodorante / nutritivo / creme | L27: 56.4
B28: Natura | C28: Tododia | D28: Hidrante Desodorante Corporal | E28: =TRIM(CONCATENATE(D28, " ", C28, " ", F28, " ", IF(G28>0, G28 & "x" & H28, H28), " ", I28)) | F28: Cereja Negra e Praliné | H28: 400ml | I28: Refil | J28: Desodorante / nutritivo / creme | L28: 56.4
A29: NATBRA-99137 | B29: Natura | C29: Tododia | D29: Hidrante Desodorante Corporal | E29: =TRIM(CONCATENATE(D29, " ", C29, " ", F29, " ", IF(G29>0, G29 & "x" & H29, H29), " ", I29)) | F29: Cereja e Avela | H29: 400ml | I29: Refil | J29: Desodorante / nutritivo / creme | L29: 56.4
B30: Natura | C30: Tododia | D30: Hidrante Desodorante Corporal | E30: =TRIM(CONCATENATE(D30, " ", C30, " ", F30, " ", IF(G30>0, G30 & "x" & H30, H30), " ", I30)) | F30: Todonoite | H30: 400ml | I30: Refil | J30: Hidrata. Noturno \ calmante | L30: 56.4
B31: Natura | C31: Tododia | D31: Hidrante Desodorante Corporal | E31: =TRIM(CONCATENATE(D31, " ", C31, " ", F31, " ", IF(G31>0, G31 & "x" & H31, H31), " ", I31)) | F31: Todonoite | H31: 200ml | I31: Refil | J31: Hidrata. Noturno \ calmante
A32: NATBRA-152290 | B32: Natura | C32: Tododia | D32: Hidrante Desodorante Corporal | E32: =TRIM(CONCATENATE(D32, " ", C32, " ", F32, " ", IF(G32>0, G32 & "x" & H32, H32), " ", I32)) | F32: Flor de Gengibre e Tangerina | H32: 400ml | I32: Refil | J32: Hidrata. Noturno \ calmante | L32: 56.4
B33: Natura | C33: Tododia | D33: Hidrante Desodorante Corporal | E33: =TRIM(CONCATENATE(D33, " ", C33, " ", F33, " ", IF(G33>0, G33 & "x" & H33, H33), " ", I33)) | F33: Flor de Pera e Melissa | H33: 400ml | I33: Refil | J33: Desodorante / nutritivo / creme | L33: 56.4
B34: Natura | C34: Tododia | D34: Hidrante Desodorante Corporal | E34: =TRIM(CONCATENATE(D34, " ", C34, " ", F34, " ", IF(G34>0, G34 & "x" & H34, H34), " ", I34)) | F34: Framboesa e PImenta Vermelha | H34: 400ml | I34: Refil | J34: Desodorante / nutritivo / creme | L34: 56.4
B35: Natura | C35: Tododia | D35: Hidrante Desodorante Corporal | E35: =TRIM(CONCATENATE(D35, " ", C35, " ", F35, " ", IF(G35>0, G35 & "x" & H35, H35), " ", I35)) | F35: Jambo Rosa e Flor De Caju | H35: 400ml | I35: Refil | J35: Desodorante / nutritivo / creme | L35: 56.4
B36: Natura | C36: Tododia | D36: Hidrante Desodorante Corporal | E36: =TRIM(CONCATENATE(D36, " ", C36, " ", F36, " ", IF(G36>0, G36 & "x" & H36, H36), " ", I36)) | F36: Limão Siciliano e Flor de Gardênia | H36: 400ml | I36: Refil | J36: Nutritivo Energizante | L36: 56.4
B37: Natura | C37: Tododia | D37: Hidrante Desodorante Corporal | E37: =TRIM(CONCATENATE(D37, " ", C37, " ", F37, " ", IF(G37>0, G37 & "x" & H37, H37), " ", I37)) | F37: Macadâmia | H37: 400ml | I37: Refil | J37: Desodorante / nutritivo / creme | L37: 56.4
B38: Natura | C38: Tododia | D38: Hidrante Desodorante Corporal | E38: =TRIM(CONCATENATE(D38, " ", C38, " ", F38, " ", IF(G38>0, G38 & "x" & H38, H38), " ", I38)) | F38: Maça Caramelada e Baunilha | H38: 400ml | I38: Refil | J38: Nutritivo \ Especial São João \ Inspirada na Maçã do Amor | L38: 56.4
B39: Natura | C39: Tododia | D39: Hidrante Desodorante Corporal | E39: =TRIM(CONCATENATE(D39, " ", C39, " ", F39, " ", IF(G39>0, G39 & "x" & H39, H39), " ", I39)) | F39: Manga Rosa e Àgua de Coco | H39: 400ml | I39: Refil | J39: Refrescante / Gelado | L39: 56.4
B40: Natura | C40: Tododia | D40: Hidrante Desodorante Corporal | E40: =TRIM(CONCATENATE(D40, " ", C40, " ", F40, " ", IF(G40>0, G40 & "x" & H40, H40), " ", I40)) | F40: Nóz Pecão e Cacau | H40: 400ml | I40: Refil | J40: Desodorante / nutritivo / creme | L40: 56.4
B41: Natura | C41: Tododia | D41: Hidrante Desodorante Corporal | E41: =TRIM(CONCATENATE(D41, " ", C41, " ", F41, " ", IF(G41>0, G41 & "x" & H41, H41), " ", I41)) | F41: Romã e Flor de Amora | H41: 400ml | I41: Refil | J41: Desodorante / nutritivo / creme | L41: 56.4
B42: Natura | C42: Tododia | D42: Hidrante Desodorante Corporal | E42: =TRIM(CONCATENATE(D42, " ", C42, " ", F42, " ", IF(G42>0, G42 & "x" & H42, H42), " ", I42)) | F42: Tâmara e Canela | H42: 400ml | I42: Refil | J42: Desodorante / nutritivo / creme | L42: 56.4
B43: Natura | C43: Tododia | D43: Creme Hidratante | E43: =TRIM(CONCATENATE(D43, " ", C43, " ", F43, " ", IF(G43>0, G43 & "x" & H43, H43), " ", I43)) | F43: Todonoite | H43: 200ml | I43: Pote | J43: Creme Hidrat. Prebiotica \ Vitam +B5 \ Para Massagem | L43: 81.9
B44: Natura | C44: Tododia | D44: Creme Hidratante | E44: =TRIM(CONCATENATE(D44, " ", C44, " ", F44, " ", IF(G44>0, G44 & "x" & H44, H44), " ", I44)) | F44: Cereja e Avelã | H44: 200ml | I44: Pote | J44: Creme Amanteigado \ Perfumado \ Desodorante
B45: Natura | C45: Tododia | D45: Creme Hidratante | E45: =TRIM(CONCATENATE(D45, " ", C45, " ", F45, " ", IF(G45>0, G45 & "x" & H45, H45), " ", I45)) | F45: Cereja Negra e Praliné | H45: 250g | I45: Pote | J45: Pele Macia \\ Como Veludo \\ HIdrata. e PErfuma 2x Mais | L45: 81.9
B46: Natura | C46: Tododia | D46: Manteiga Creme Corporal | E46: =TRIM(CONCATENATE(D46, " ", C46, " ", F46, " ", IF(G46>0, G46 & "x" & H46, H46), " ", I46)) | F46: Jambo Rosa e Flor De Caju | H46: 200g | I46: Pote | J46: Hidratante / Manteiga para o corpo hidrata \ Uniformiza \ Desodorante | L46: 81.9
B47: Natura | C47: Tododia | D47: Oleo Creme Corporal | E47: =TRIM(CONCATENATE(D47, " ", C47, " ", F47, " ", IF(G47>0, G47 & "x" & H47, H47), " ", I47)) | F47: Jambo Rosa e Flor De Caju | H47: 200ml | I47: Pote | J47: Ultranutritivo \ Restaurador \ Desodorante | L47: 81.9
...

Sheet Movimento
A1: Data | B1: COD do Produto | C1: Produto | D1: Cliente | E1: Tipo de Movimentação | F1: Quantidade | G1: Preço Custo Total | H1: Preço Venda Total | I1: Observações | J1: Status | K1: Data Prevista | L1: Tipo de Pagamento | M1: ID_Venda
A2: 45992.599 | B2: NATBRA-2816 | C2: Natura Hidrante Desodorante Corporal Tododia Algodão 400ml Frasco | D2: NATURA | E2: ENTRADA | F2: 5 | G2: 320 | H2: 379.5 | I2: Ciclo 23 | J2: PAGO | K2: 45993 | L2: Pix | M2: E-27B7FB
A3: 45992.599 | B3: NATBRA-2816 | C3: Natura Hidrante Desodorante Corporal Tododia Algodão 400ml Frasco | D3: ASD | E3: SAÍDA | F3: -1 | G3: -64 | H3: 75.9 | J3: PAGO | K3: 2025-12-01 14:22:36 | L3: Pix | M3: V-C8C229
A4: 45993.599 | B4: NATBRA-190159 | C4: =VLOOKUP(B4,Produtos!$A:$E,5,FALSE) | D4: NATURA | E4: ENTRADA | F4: 1 | G4: 21.23 | H4: 0 | J4: PAGO | L4: Pix
A5: 45994.599 | B5: NATBRA-152290 | C5: =VLOOKUP(B5,Produtos!$A:$E,5,FALSE) | D5: NATURA | E5: ENTRADA | F5: 1 | G5: 21.23 | H5: 0 | J5: PAGO | L5: Pix
A6: 45995.599 | B6: NATBRA-116779 | C6: =VLOOKUP(B6,Produtos!$A:$E,5,FALSE) | D6: NATURA | E6: ENTRADA | F6: 3 | G6: 91.76 | H6: 0 | J6: PAGO | L6: Pix
A7: 45996.599 | B7: NATBRA-959847 | C7: =VLOOKUP(B7,Produtos!$A:$E,5,FALSE) | D7: NATURA | E7: ENTRADA | F7: 3 | G7: 236.06 | H7: 0 | J7: PAGO | L7: Pix
A8: 45997.599 | B8: NATBRA-112866 | C8: =VLOOKUP(B8,Produtos!$A:$E,5,FALSE) | D8: NATURA | E8: ENTRADA | F8: 3 | G8: 36.95 | H8: 0 | J8: PAGO | L8: Pix
A9: 45998.599 | B9: NATBRA-159951 | C9: =VLOOKUP(B9,Produtos!$A:$E,5,FALSE) | D9: NATURA | E9: ENTRADA | F9: 3 | G9: 59.95 | H9: 0 | J9: PAGO | L9: Pix
A10: 45999.599 | B10: NATBRA-782675 | C10: =VLOOKUP(B10,Produtos!$A:$E,5,FALSE) | D10: NATURA | E10: ENTRADA | F10: 3 | G10: 177.13 | H10: 0 | J10: PAGO | L10: Pix
A11: 46000.599 | B11: NATBRA-817061 | C11: =VLOOKUP(B11,Produtos!$A:$E,5,FALSE) | D11: NATURA | E11: ENTRADA | F11: 3 | G11: 204.52 | H11: 0 | J11: PAGO | L11: Pix
A12: 46001.599 | B12: NATBRA-817060 | C12: =VLOOKUP(B12,Produtos!$A:$E,5,FALSE) | D12: NATURA | E12: ENTRADA | F12: 3 | G12: 56.37 | H12: 0 | J12: PAGO | L12: Pix
A13: 46003.599 | B13: NATBRA-149374 | C13: =VLOOKUP(B13,Produtos!$A:$E,5,FALSE) | D13: NATURA | E13: ENTRADA | F13: 3 | G13: 38.95 | H13: 0 | J13: PAGO | L13: Pix
A14: 46005.599 | B14: NATBRA-151033 | C14: =VLOOKUP(B14,Produtos!$A:$E,5,FALSE) | D14: NATURA | E14: ENTRADA | F14: 2 | G14: 31.25 | H14: 0 | J14: PAGO | L14: Pix
A15: 46006.599 | B15: NATBRA-9467 | C15: =VLOOKUP(B15,Produtos!$A:$E,5,FALSE) | D15: NATURA | E15: ENTRADA | F15: 2 | G15: 194.34 | H15: 0 | J15: PAGO | L15: Pix
... A56: 46052.599 | B56: NATBRA-56747 | C56: =VLOOKUP(B56,Produtos!$A:$E,5,FALSE) | D56: NATURA | E56: ENTRADA | F56: 3 | G56: 49.34 | H56: 0 | J56: PAGO | L56: Pix

Sheet Clientes
A1: ID_Cliente | B1: Nome | C1: Telefone | D1: Email | E1: Endereço | F1: Observações
A2: C-C2BFEE | B2: Joana | C2: 11 92393287 | D2: dsadsa@gmail.com | E2: Cachoeira | F2: Loja Whats
A3: C-4C4B74 | B3: ASDDAS | C3: 2232 | D3: sadlapsd@gmail.com | E3: Furnas | F3: Site
A4: C-0947A0 | B4: FGGH | C4: asdasd | D4: asdasd | E4: asd | F4: dasda
A5: C-7482A8 | B5: GHHHH | F5: Cadastrado via Venda

Sheet Relatorio
A1: FATURAMENTO BRUTO | B1: =SUMIFS(Movimento!H:H, Movimento!E:E, "SAÍDA", Movimento!J:J, "PAGO")
A2: CUSTO DE MERCADORIA VENDIDA (CMV) | B2: =SUMIFS(Movimento!G:G, Movimento!E:E, "SAÍDA") * -1
A3: LUCRO BRUTO TOTAL | B3: =B1 - B2
A4: MARGEM BRUTA (%) | B4: =(B3 / B1)
A5: QTD PRODUTOS FIADO | B5: =SUMIFS(Movimento!F:F, Movimento!J:J, "A RECEBER") * -1
A6: VALOR A RECEBER (FIADO) | B6: =SUMIFS(Movimento!H:H, Movimento!J:J, "A RECEBER")
A7: ESTOQUE TOTAL (ITENS) | B7: =SUM(Movimento!F:F)
A8: CUSTO TOTAL DO ESTOQUE ATUAL | B8: =SUM(Movimento!G:G)
A9: SALDO DE CAIXA DO ESTOQUE | B9: =B1- B8
