Workbook

Sheet Produtos
A1: COD | B1: Marca | C1: Coleção | D1: Categoria | E1: Produto | F1: Nome | G1: Unidade | H1: Volume | I1: Tipo | J1: Descrição | K1: Preço Custo | L1: Preço Venda | M1: Estoque | N1: Status estoque
B2: Natura | C2: Tododia | D2: Hidrante Desodorante Corporal | E2: =TRIM(CONCATENATE(C2, " ", D2, " ", F2, " ", IF(G2>0, G2 & "x" & H2, H2), " ", I2)) -> Tododia Hidrante Desodorante Corporal Algodão 400ml Frasco | F2: Algodão | H2: 400ml | I2: Frasco | J2: Desodorante / nutritivo / creme | K2: 76 | L2: 76 | M2: =SUMIF(Movimento!B:B, A2, Movimento!F:F) -> 0 | N2: =IF(M2=0,"Falta Pedir!",IF(M2<=3,"Baixo Estoque","Em Estoque")) -> Falta Pedir!
B3: Natura | C3: Tododia | D3: Hidrante Desodorante Corporal | E3: =TRIM(CONCATENATE(C3, " ", D3, " ", F3, " ", IF(G3>0, G3 & "x" & H3, H3), " ", I3)) -> Tododia Hidrante Desodorante Corporal Ameixa e Flor de Baunilha 400ml Frasco | F3: Ameixa e Flor de Baunilha | H3: 400ml | I3: Frasco | J3: Suave de Algodão \ Nutritivo | K3: 75.9 | L3: 75.9 | M3: =SUMIF(Movimento!B:B, A3, Movimento!F:F) -> 0 | N3: =IF(M3=0,"Falta Pedir!",IF(M3<=3,"Baixo Estoque","Em Estoque")) -> Falta Pedir!
B4: Natura | C4: Tododia | D4: Hidrante Desodorante Corporal | E4: =TRIM(CONCATENATE(C4, " ", D4, " ", F4, " ", IF(G4>0, G4 & "x" & H4, H4), " ", I4)) -> Tododia Hidrante Desodorante Corporal Acerola e Hibisco 400ml Frasco | F4: Acerola e Hibisco | H4: 400ml | I4: Frasco | J4: Refrescante / Gelado | K4: 75.9 | L4: 75.9
B5: Natura | C5: Tododia | D5: Hidrante Desodorante Corporal | E5: =TRIM(CONCATENATE(C5, " ", D5, " ", F5, " ", IF(G5>0, G5 & "x" & H5, H5), " ", I5)) -> Tododia Hidrante Desodorante Corporal Amora Vermelha e Jabuticaba 400ml Frasco | F5: Amora Vermelha e Jabuticaba | H5: 400ml | I5: Frasco | J5: Desodorante / nutritivo / creme | K5: 75.9 | L5: 75.9
B6: Natura | C6: Tododia | D6: Hidrante Desodorante Corporal | E6: =TRIM(CONCATENATE(C6, " ", D6, " ", F6, " ", IF(G6>0, G6 & "x" & H6, H6), " ", I6)) -> Tododia Hidrante Desodorante Corporal Capim Limão e Hortelã 400ml Frasco | F6: Capim Limão e Hortelã | H6: 400ml | I6: Frasco | J6: Desodorante / nutritivo / creme | K6: 75.9 | L6: 75.9
B7: Natura | C7: Tododia | D7: Hidrante Desodorante Corporal | E7: =TRIM(CONCATENATE(C7, " ", D7, " ", F7, " ", IF(G7>0, G7 & "x" & H7, H7), " ", I7)) -> Tododia Hidrante Desodorante Corporal Cereja Negra e Praliné 400ml Frasco | F7: Cereja Negra e Praliné | H7: 400ml | I7: Frasco | J7: Desodorante / nutritivo / creme | K7: 75.9 | L7: 75.9
B8: Natura | C8: Tododia | D8: Hidrante Desodorante Corporal | E8: =TRIM(CONCATENATE(C8, " ", D8, " ", F8, " ", IF(G8>0, G8 & "x" & H8, H8), " ", I8)) -> Tododia Hidrante Desodorante Corporal Cereja e Avela 400ml Frasco | F8: Cereja e Avela | H8: 400ml | I8: Frasco | J8: Desodorante / nutritivo / creme | K8: 75.9 | L8: 75.9
B9: Natura | C9: Tododia | D9: Hidrante Desodorante Corporal | E9: =TRIM(CONCATENATE(C9, " ", D9, " ", F9, " ", IF(G9>0, G9 & "x" & H9, H9), " ", I9)) -> Tododia Hidrante Desodorante Corporal Chá de Camomila e Lavanda 400ml Frasco | F9: Chá de Camomila e Lavanda | H9: 400ml | I9: Frasco | J9: HIdrata. Noturno \ calmante | K9: 75.9 | L9: 75.9
B10: Natura | C10: Tododia | D10: Hidrante Desodorante Corporal | E10: =TRIM(CONCATENATE(C10, " ", D10, " ", F10, " ", IF(G10>0, G10 & "x" & H10, H10), " ", I10)) -> Tododia Hidrante Desodorante Corporal Chá de Camomila e Lavanda 200ml Frasco | F10: Chá de Camomila e Lavanda | H10: 200ml | I10: Frasco | J10: HIdrata. Noturno \ calmante
B11: Natura | C11: Tododia | D11: Hidrante Desodorante Corporal | E11: =TRIM(CONCATENATE(C11, " ", D11, " ", F11, " ", IF(G11>0, G11 & "x" & H11, H11), " ", I11)) -> Tododia Hidrante Desodorante Corporal Flor de Gengibre e Tangerina 400 ml Frasco | F11: Flor de Gengibre e Tangerina | H11: 400 ml | I11: Frasco | J11: Nutritivo Energizante | K11: 75.9 | L11: 75.9
B12: Natura | C12: Tododia | D12: Hidrante Desodorante Corporal | E12: =TRIM(CONCATENATE(C12, " ", D12, " ", F12, " ", IF(G12>0, G12 & "x" & H12, H12), " ", I12)) -> Tododia Hidrante Desodorante Corporal Flor de Pera e Melissa 400ml Frasco | F12: Flor de Pera e Melissa | H12: 400ml | I12: Frasco | J12: Desodorante / nutritivo / creme | K12: 75.9 | L12: 75.9
B13: Natura | C13: Tododia | D13: Hidrante Desodorante Corporal | E13: =TRIM(CONCATENATE(C13, " ", D13, " ", F13, " ", IF(G13>0, G13 & "x" & H13, H13), " ", I13)) -> Tododia Hidrante Desodorante Corporal Framboesa e PImenta Vermelha 400ml Frasco | F13: Framboesa e PImenta Vermelha | H13: 400ml | I13: Frasco | J13: Desodorante / nutritivo / creme | K13: 75.9 | L13: 75.9
B14: Natura | C14: Tododia | D14: Hidrante Desodorante Corporal | E14: =TRIM(CONCATENATE(C14, " ", D14, " ", F14, " ", IF(G14>0, G14 & "x" & H14, H14), " ", I14)) -> Tododia Hidrante Desodorante Corporal Jambo Rosa e Flor De Caju 400ml Frasco | F14: Jambo Rosa e Flor De Caju | H14: 400ml | I14: Frasco | J14: Desodorante / nutritivo / creme | K14: 75.9 | L14: 75.9
B15: Natura | C15: Tododia | D15: Hidrante Desodorante Corporal | E15: =TRIM(CONCATENATE(C15, " ", D15, " ", F15, " ", IF(G15>0, G15 & "x" & H15, H15), " ", I15)) -> Tododia Hidrante Desodorante Corporal Limão Siciliano e Flor de Gardênia 400ml Frasco | F15: Limão Siciliano e Flor de Gardênia | H15: 400ml | I15: Frasco | J15: Desodorante / nutritivo / creme | K15: 75.9 | L15: 75.9
B16: Natura | C16: Tododia | D16: Hidrante Desodorante Corporal | E16: =TRIM(CONCATENATE(C16, " ", D16, " ", F16, " ", IF(G16>0, G16 & "x" & H16, H16), " ", I16)) -> Tododia Hidrante Desodorante Corporal Macadâmia 400ml Frasco | F16: Macadâmia | H16: 400ml | I16: Frasco | J16: Desodorante / nutritivo / creme | K16: 75.9 | L16: 75.9
B17: Natura | C17: Tododia | D17: Hidrante Desodorante Corporal | E17: =TRIM(CONCATENATE(C17, " ", D17, " ", F17, " ", IF(G17>0, G17 & "x" & H17, H17), " ", I17)) -> Tododia Hidrante Desodorante Corporal Maça Caramelada e Baunilha 400ml Frasco | F17: Maça Caramelada e Baunilha | H17: 400ml | I17: Frasco | J17: Nutritivo \ Especial São João \ Inspirada na Maçã do Amor | K17: 75.9 | L17: 75.9
B18: Natura | C18: Tododia | D18: Hidrante Desodorante Corporal | E18: =TRIM(CONCATENATE(C18, " ", D18, " ", F18, " ", IF(G18>0, G18 & "x" & H18, H18), " ", I18)) -> Tododia Hidrante Desodorante Corporal Manga Rosa e Àgua de Coco 400ml Frasco | F18: Manga Rosa e Àgua de Coco | H18: 400ml | I18: Frasco | J18: Refrescante / Gelado | K18: 75.9 | L18: 75.9
B19: Natura | C19: Tododia | D19: Hidrante Desodorante Corporal | E19: =TRIM(CONCATENATE(C19, " ", D19, " ", F19, " ", IF(G19>0, G19 & "x" & H19, H19), " ", I19)) -> Tododia Hidrante Desodorante Corporal Nóz Pecão e Cacau 400ml Frasco | F19: Nóz Pecão e Cacau | H19: 400ml | I19: Frasco | J19: Desodorante / nutritivo / creme | K19: 75.9 | L19: 75.9
B20: Natura | C20: Tododia | D20: Hidrante Desodorante Corporal | E20: =TRIM(CONCATENATE(C20, " ", D20, " ", F20, " ", IF(G20>0, G20 & "x" & H20, H20), " ", I20)) -> Tododia Hidrante Desodorante Corporal Roma e Salvia 400ml Frasco | F20: Roma e Salvia | H20: 400ml | I20: Frasco | J20: Desodorante / nutritivo / creme | K20: 75.9 | L20: 75.9
B21: Natura | C21: Tododia | D21: Hidrante Desodorante Corporal | E21: =TRIM(CONCATENATE(C21, " ", D21, " ", F21, " ", IF(G21>0, G21 & "x" & H21, H21), " ", I21)) -> Tododia Hidrante Desodorante Corporal Romã e Flor de Amora 400ml Frasco | F21: Romã e Flor de Amora | H21: 400ml | I21: Frasco | J21: Desodorante / nutritivo / creme | K21: 75.9 | L21: 75.9
B22: Natura | C22: Tododia | D22: Hidrante Desodorante Corporal | E22: =TRIM(CONCATENATE(C22, " ", D22, " ", F22, " ", IF(G22>0, G22 & "x" & H22, H22), " ", I22)) -> Tododia Hidrante Desodorante Corporal Tâmara e Canela 400ml Frasco | F22: Tâmara e Canela | H22: 400ml | I22: Frasco | J22: Desodorante / nutritivo / creme | K22: 75.9 | L22: 75.9
... B30: Natura | C30: Tododia | D30: Hidrante Desodorante Corporal | E30: =TRIM(CONCATENATE(C30, " ", D30, " ", F30, " ", IF(G30>0, G30 & "x" & H30, H30), " ", I30)) -> Tododia Hidrante Desodorante Corporal Chá de Camomila e Lavanda 400ml Refil | F30: Chá de Camomila e Lavanda | H30: 400ml | I30: Refil | J30: Hidrata. Noturno \ calmante | K30: 56.4 | L30: 56.4
B31: Natura | C31: Tododia | D31: Hidrante Desodorante Corporal | E31: =TRIM(CONCATENATE(C31, " ", D31, " ", F31, " ", IF(G31>0, G31 & "x" & H31, H31), " ", I31)) -> Tododia Hidrante Desodorante Corporal Chá de Camomila e Lavanda 200ml Refil | F31: Chá de Camomila e Lavanda | H31: 200ml | I31: Refil | J31: Hidrata. Noturno \ calmante
B32: Natura | C32: Tododia | D32: Hidrante Desodorante Corporal | E32: =TRIM(CONCATENATE(C32, " ", D32, " ", F32, " ", IF(G32>0, G32 & "x" & H32, H32), " ", I32)) -> Tododia Hidrante Desodorante Corporal Flor de Gengibre e Tangerina 400ml Refil | F32: Flor de Gengibre e Tangerina | H32: 400ml | I32: Refil | J32: Hidrata. Noturno \ calmante | K32: 56.4 | L32: 56.4
B33: Natura | C33: Tododia | D33: Hidrante Desodorante Corporal | E33: =TRIM(CONCATENATE(C33, " ", D33, " ", F33, " ", IF(G33>0, G33 & "x" & H33, H33), " ", I33)) -> Tododia Hidrante Desodorante Corporal Flor de Pera e Melissa 400ml Refil | F33: Flor de Pera e Melissa | H33: 400ml | I33: Refil | J33: Desodorante / nutritivo / creme | K33: 56.4 | L33: 56.4
B34: Natura | C34: Tododia | D34: Hidrante Desodorante Corporal | E34: =TRIM(CONCATENATE(C34, " ", D34, " ", F34, " ", IF(G34>0, G34 & "x" & H34, H34), " ", I34)) -> Tododia Hidrante Desodorante Corporal Framboesa e PImenta Vermelha 400ml Refil | F34: Framboesa e PImenta Vermelha | H34: 400ml | I34: Refil | J34: Desodorante / nutritivo / creme | K34: 56.4 | L34: 56.4
B35: Natura | C35: Tododia | D35: Hidrante Desodorante Corporal | E35: =TRIM(CONCATENATE(C35, " ", D35, " ", F35, " ", IF(G35>0, G35 & "x" & H35, H35), " ", I35)) -> Tododia Hidrante Desodorante Corporal Jambo Rosa e Flor De Caju 400ml Refil | F35: Jambo Rosa e Flor De Caju | H35: 400ml | I35: Refil | J35: Desodorante / nutritivo / creme | K35: 56.4 | L35: 56.4
B36: Natura | C36: Tododia | D36: Hidrante Desodorante Corporal | E36: =TRIM(CONCATENATE(C36, " ", D36, " ", F36, " ", IF(G36>0, G36 & "x" & H36, H36), " ", I36)) -> Tododia Hidrante Desodorante Corporal Limão Siciliano e Flor de Gardênia 400ml Refil | F36: Limão Siciliano e Flor de Gardênia | H36: 400ml | I36: Refil | J36: Nutritivo Energizante | K36: 56.4 | L36: 56.4
B37: Natura | C37: Tododia | D37: Hidrante Desodorante Corporal | E37: =TRIM(CONCATENATE(C37, " ", D37, " ", F37, " ", IF(G37>0, G37 & "x" & H37, H37), " ", I37)) -> Tododia Hidrante Desodorante Corporal Macadâmia 400ml Refil | F37: Macadâmia | H37: 400ml | I37: Refil | J37: Desodorante / nutritivo / creme | K37: 56.4 | L37: 56.4
B38: Natura | C38: Tododia | D38: Hidrante Desodorante Corporal | E38: =TRIM(CONCATENATE(C38, " ", D38, " ", F38, " ", IF(G38>0, G38 & "x" & H38, H38), " ", I38)) -> Tododia Hidrante Desodorante Corporal Maça Caramelada e Baunilha 400ml Refil | F38: Maça Caramelada e Baunilha | H38: 400ml | I38: Refil | J38: Nutritivo \ Especial São João \ Inspirada na Maçã do Amor | K38: 56.4 | L38: 56.4
B39: Natura | C39: Tododia | D39: Hidrante Desodorante Corporal | E39: =TRIM(CONCATENATE(C39, " ", D39, " ", F39, " ", IF(G39>0, G39 & "x" & H39, H39), " ", I39)) -> Tododia Hidrante Desodorante Corporal Manga Rosa e Àgua de Coco 400ml Refil | F39: Manga Rosa e Àgua de Coco | H39: 400ml | I39: Refil | J39: Refrescante / Gelado | K39: 56.4 | L39: 56.4
B40: Natura | C40: Tododia | D40: Hidrante Desodorante Corporal | E40: =TRIM(CONCATENATE(C40, " ", D40, " ", F40, " ", IF(G40>0, G40 & "x" & H40, H40), " ", I40)) -> Tododia Hidrante Desodorante Corporal Nóz Pecão e Cacau 400ml Refil | F40: Nóz Pecão e Cacau | H40: 400ml | I40: Refil | J40: Desodorante / nutritivo / creme | K40: 56.4 | L40: 56.4
B41: Natura | C41: Tododia | D41: Hidrante Desodorante Corporal | E41: =TRIM(CONCATENATE(C41, " ", D41, " ", F41, " ", IF(G41>0, G41 & "x" & H41, H41), " ", I41)) -> Tododia Hidrante Desodorante Corporal Romã e Flor de Amora 400ml Refil | F41: Romã e Flor de Amora | H41: 400ml | I41: Refil | J41: Desodorante / nutritivo / creme | K41: 56.4 | L41: 56.4
B42: Natura | C42: Tododia | D42: Hidrante Desodorante Corporal | E42: =TRIM(CONCATENATE(C42, " ", D42, " ", F42, " ", IF(G42>0, G42 & "x" & H42, H42), " ", I42)) -> Tododia Hidrante Desodorante Corporal Tâmara e Canela 400ml Refil | F42: Tâmara e Canela | H42: 400ml | I42: Refil | J42: Desodorante / nutritivo / creme | K42: 56.4 | L42: 56.4
B43: Natura | C43: Tododia | D43: Creme Hidratante | E43: =TRIM(CONCATENATE(C43, " ", D43, " ", F43, " ", IF(G43>0, G43 & "x" & H43, H43), " ", I43)) -> Tododia Creme Hidratante Chá de Camomila e Lavanda 200ml Pote | F43: Chá de Camomila e Lavanda | H43: 200ml | I43: Pote | J43: Creme Hidrat. Prebiotica \ Vitam +B5 \ Para Massagem | K43: 81.9 | L43: 81.9
B44: Natura | C44: Tododia | D44: Creme Hidratante | E44: =TRIM(CONCATENATE(C44, " ", D44, " ", F44, " ", IF(G44>0, G44 & "x" & H44, H44), " ", I44)) -> Tododia Creme Hidratante Cereja e Avelã 200ml Pote | F44: Cereja e Avelã | H44: 200ml | I44: Pote | J44: Creme Amanteigado \ Perfumado \ Desodorante
B45: Natura | C45: Tododia | D45: Creme Hidratante | E45: =TRIM(CONCATENATE(C45, " ", D45, " ", F45, " ", IF(G45>0, G45 & "x" & H45, H45), " ", I45)) -> Tododia Creme Hidratante Cereja Negra e Praliné 250g Pote | F45: Cereja Negra e Praliné | H45: 250g | I45: Pote | J45: Pele Macia \\ Como Veludo \\ HIdrata. e PErfuma 2x Mais | K45: 81.9 | L45: 81.9
B46: Natura | C46: Tododia | D46: Manteiga Creme Corporal | E46: =TRIM(CONCATENATE(C46, " ", D46, " ", F46, " ", IF(G46>0, G46 & "x" & H46, H46), " ", I46)) -> Tododia Manteiga Creme Corporal Jambo Rosa e Flor De Caju 200g Pote | F46: Jambo Rosa e Flor De Caju | H46: 200g | I46: Pote | J46: Hidratante / Manteiga para o corpo hidrata \ Uniformiza \ Desodorante | K46: 81.9 | L46: 81.9
B47: Natura | C47: Tododia | D47: Oleo Creme Corporal | E47: =TRIM(CONCATENATE(C47, " ", D47, " ", F47, " ", IF(G47>0, G47 & "x" & H47, H47), " ", I47)) -> Tododia Oleo Creme Corporal Jambo Rosa e Flor De Caju 200ml Pote | F47: Jambo Rosa e Flor De Caju | H47: 200ml | I47: Pote | J47: Ultranutritivo \ Restaurador \ Desodorante | K47: 81.9 | L47: 81.9
...

Sheet Movimento
A1: Data | B1: COD do Produto | C1: Produto | D1: Cliente | E1: Tipo de Movimentação | F1: Quantidade | G1: Preço Custo Total | H1: Preço Venda Total | I1: Observações | J1: Status | K1: Data Prevista | L1: Tipo de Pagamento | M1: ID_Venda
A2: 45963.238 | B2: 1 | C2: Natura Hidrante Desodorante Corporal Tododia Algodão 400ml Frasco | D2: ASD | E2: SAÍDA | F2: -1 | G2: -76 | H2: 180 | I2: ASDASDSAD | J2: PAGO | K2: 45963.238 | L2: Pix | M2: V-23A77E
A3: 45963.245 | B3: 1 | C3: Natura Hidrante Desodorante Corporal Tododia Algodão 400ml Frasco | D3: GHHHH | E3: SAÍDA | F3: -1 | G3: -76 | H3: 180 | I3: aa | J3: PAGO | K3: 45963.245 | L3: Pix | M3: V-A4BAD1
A4: 45963.247 | B4: 1 | C4: Natura Hidrante Desodorante Corporal Tododia Algodão 400ml Frasco | D4: ASDDAS | E4: SAÍDA | F4: 0 | G4: 0 | H4: 90 | I4: Parcela 1/2 | J4: A RECEBER | K4: 45963 | L4: Parcelado | M4: V-4F0824
A5: 45963.247 | B5: 1 | C5: Natura Hidrante Desodorante Corporal Tododia Algodão 400ml Frasco | D5: ASDDAS | E5: SAÍDA | F5: -1 | G5: -76 | H5: 90 | I5: Parcela 2/2 | J5: A RECEBER | K5: 45993 | L5: Parcelado | M5: V-4F0824
A6: 45963.251 | B6: 2 | C6: Natura Hidrante Desodorante Corporal Tododia Ameixa e Flor de Baunilha 400ml Frasco | D6: GHHHH | E6: SAÍDA | F6: 0 | G6: 0 | H6: 229 | I6: Parcela 1/2 | a | J6: A RECEBER | K6: 45963 | L6: Parcelado | M6: V-059D98
A7: 45963.251 | B7: 2 | C7: Natura Hidrante Desodorante Corporal Tododia Ameixa e Flor de Baunilha 400ml Frasco | D7: GHHHH | E7: SAÍDA | F7: -1 | G7: -75.9 | H7: 229 | I7: Parcela 2/2 | a | J7: A RECEBER | K7: 45993 | L7: Parcelado | M7: V-059D98
A8: 45963.251 | B8: 1 | C8: Natura Hidrante Desodorante Corporal Tododia Algodão 400ml Frasco | D8: GHHHH | E8: SAÍDA | F8: 0 | G8: 0 | H8: 229 | I8: Parcela 1/2 | a | J8: A RECEBER | K8: 45963 | L8: Parcelado | M8: V-059D98
A9: 45963.251 | B9: 1 | C9: Natura Hidrante Desodorante Corporal Tododia Algodão 400ml Frasco | D9: GHHHH | E9: SAÍDA | F9: -1 | G9: -76 | H9: 229 | I9: Parcela 2/2 | a | J9: A RECEBER | K9: 45993 | L9: Parcelado | M9: V-059D98
A10: 45963.265 | B10: 1 | C10: Natura Hidrante Desodorante Corporal Tododia Algodão 400ml Frasco | D10: Natura | E10: ENTRADA | F10: 3 | G10: 228 | H10: 540 | J10: PAGO | K10: 45964 | L10: Pix | M10: E-766FE7
A11: 45963.266 | B11: 1 | C11: Natura Hidrante Desodorante Corporal Tododia Algodão 400ml Frasco | D11: Natura | E11: ENTRADA | F11: 5 | G11: 380 | H11: 900 | I11: Ciclo 26 | J11: PAGO | K11: 45964 | L11: Pix | M11: E-37A388
A12: 45963.278 | B12: 2 | C12: Natura Hidrante Desodorante Corporal Tododia Ameixa e Flor de Baunilha 400ml Frasco | D12: ASD | E12: SAÍDA | F12: -1 | G12: -75.9 | H12: 278 | J12: PAGO | K12: 45963.278 | L12: Pix | M12: V-DA3106
A13: 45963.278 | B13: 1 | C13: Natura Hidrante Desodorante Corporal Tododia Algodão 400ml Frasco | D13: ASD | E13: SAÍDA | F13: -1 | G13: -76 | H13: 180 | I13: 1 | J13: A RECEBER | K13: 45963 | L13: Fiado | M13: V-1567C2
A14: 45963.303 | B14: 2 | C14: Natura Hidrante Desodorante Corporal Tododia Ameixa e Flor de Baunilha 400ml Frasco | D14: Natura | E14: ENTRADA | F14: 6 | G14: 455.4 | H14: 1668 | J14: PAGO | K14: 2025-11-02 23:59:59 | L14: Pix | M14: E-BF13D6

Sheet Clientes
A1: ID_Cliente | B1: Nome | C1: Telefone | D1: Email | E1: Endereço | F1: Observações
A2: C-C2BFEE | B2: ASD | C2: 11 92393287 | D2: dsadsa@gmail.com | E2: Cachoeira | F2: Loja Whats
A3: C-4C4B74 | B3: ASDDAS | C3: 2232 | D3: sadlapsd@gmail.com | E3: Furnas | F3: Site
A4: C-0947A0 | B4: FGGH | C4: asdasd | D4: asdasd | E4: asd | F4: dasda
A5: C-7482A8 | B5: GHHHH | F5: Cadastrado via Venda

Sheet Relatorio
A1: FATURAMENTO BRUTO | B1: =SUMIFS(Movimento!H:H, Movimento!E:E, "SAÍDA", Movimento!J:J, "PAGO") -> 638
A2: CUSTO DE MERCADORIA VENDIDA (CMV) | B2: =SUMIFS(Movimento!G:G, Movimento!E:E, "SAÍDA") * -1 -> 531.8
A3: LUCRO BRUTO TOTAL | B3: =B1 - B2 -> 106.2
A4: MARGEM BRUTA (%) | B4: =(B3 / B1) -> 0.16645768
A5: QTD PRODUTOS FIADO | B5: =SUMIFS(Movimento!F:F, Movimento!J:J, "A RECEBER") * -1 -> 4
A6: VALOR A RECEBER (FIADO) | B6: =SUMIFS(Movimento!H:H, Movimento!J:J, "A RECEBER") -> 1276
A7: ESTOQUE TOTAL (ITENS) | B7: =SUM(Movimento!F:F) -> 7
A8: CUSTO TOTAL DO ESTOQUE ATUAL | B8: =SUM(Movimento!G:G) -> 531.6
A9: SALDO DE CAIXA DO ESTOQUE | B9: =B1- B8 -> 106.4
